Traceback (most recent call last):
  File "/home/runner/miniconda3/envs/leapfrog-fault-models/lib/python3.12/site-packages/jupyter_core/utils/__init__.py", line 154, in wrapped
    asyncio.get_running_loop()
RuntimeError: no running event loop

During handling of the above exception, another exception occurred:

Traceback (most recent call last):
  File "/home/runner/miniconda3/envs/leapfrog-fault-models/lib/python3.12/site-packages/jupyter_cache/executors/utils.py", line 58, in single_nb_execution
    executenb(
  File "/home/runner/miniconda3/envs/leapfrog-fault-models/lib/python3.12/site-packages/nbclient/client.py", line 1319, in execute
    return NotebookClient(nb=nb, resources=resources, km=km, **kwargs).execute()
           ^^^^^^^^^^^^^^^^^^^^^^^^^^^^^^^^^^^^^^^^^^^^^^^^^^^^^^^^^^^^^^^^^^^^^
  File "/home/runner/miniconda3/envs/leapfrog-fault-models/lib/python3.12/site-packages/jupyter_core/utils/__init__.py", line 158, in wrapped
    return loop.run_until_complete(inner)
           ^^^^^^^^^^^^^^^^^^^^^^^^^^^^^^
  File "/home/runner/miniconda3/envs/leapfrog-fault-models/lib/python3.12/asyncio/base_events.py", line 691, in run_until_complete
    return future.result()
           ^^^^^^^^^^^^^^^
  File "/home/runner/miniconda3/envs/leapfrog-fault-models/lib/python3.12/site-packages/nbclient/client.py", line 709, in async_execute
    await self.async_execute_cell(
  File "/home/runner/miniconda3/envs/leapfrog-fault-models/lib/python3.12/site-packages/nbclient/client.py", line 1062, in async_execute_cell
    await self._check_raise_for_error(cell, cell_index, exec_reply)
  File "/home/runner/miniconda3/envs/leapfrog-fault-models/lib/python3.12/site-packages/nbclient/client.py", line 918, in _check_raise_for_error
    raise CellExecutionError.from_cell_and_msg(cell, exec_reply_content)
nbclient.exceptions.CellExecutionError: An error occurred while executing the following cell:
------------------
# モジュールのインポート
from fault_mesh.faults.leapfrog import LeapfrogMultiFault
import os
import numpy as np
import geopandas as gpd
------------------


[31m---------------------------------------------------------------------------[39m
[31mModuleNotFoundError[39m                       Traceback (most recent call last)
[36mCell[39m[36m [39m[32mIn[1][39m[32m, line 2[39m
[32m      1[39m [38;5;66;03m# モジュールのインポート[39;00m
[32m----> [39m[32m2[39m [38;5;28;01mfrom[39;00m[38;5;250m [39m[34;01mfault_mesh[39;00m[34;01m.[39;00m[34;01mfaults[39;00m[34;01m.[39;00m[34;01mleapfrog[39;00m[38;5;250m [39m[38;5;28;01mimport[39;00m LeapfrogMultiFault
[32m      3[39m [38;5;28;01mimport[39;00m[38;5;250m [39m[34;01mos[39;00m
[32m      4[39m [38;5;28;01mimport[39;00m[38;5;250m [39m[34;01mnumpy[39;00m[38;5;250m [39m[38;5;28;01mas[39;00m[38;5;250m [39m[34;01mnp[39;00m

[36mFile [39m[32m~/miniconda3/envs/leapfrog-fault-models/lib/python3.12/site-packages/fault_mesh/faults/leapfrog.py:16[39m
[32m     14[39m [38;5;28;01mimport[39;00m[38;5;250m [39m[34;01mpandas[39;00m[38;5;250m [39m[38;5;28;01mas[39;00m[38;5;250m [39m[34;01mpd[39;00m
[32m     15[39m [38;5;28;01mimport[39;00m[38;5;250m [39m[34;01mmeshio[39;00m
[32m---> [39m[32m16[39m [38;5;28;01mimport[39;00m[38;5;250m [39m[34;01mpyvista[39;00m[38;5;250m [39m[38;5;28;01mas[39;00m[38;5;250m [39m[34;01mpv[39;00m
[32m     18[39m [38;5;28;01mfrom[39;00m[38;5;250m [39m[34;01mshapely[39;00m[34;01m.[39;00m[34;01maffinity[39;00m[38;5;250m [39m[38;5;28;01mimport[39;00m translate
[32m     19[39m [38;5;28;01mfrom[39;00m[38;5;250m [39m[34;01mshapely[39;00m[34;01m.[39;00m[34;01mops[39;00m[38;5;250m [39m[38;5;28;01mimport[39;00m unary_union

[31mModuleNotFoundError[39m: No module named 'pyvista'

